<!-- 
Copyright 2025 国地共建人形机器人创新中心/人形机器人（上海）有限公司, https://www.openloong.net/

Permission is hereby granted, free of charge, to any person obtaining a copy of this software and associated documentation files (the “Software”), to deal in the Software without restriction, including without limitation the rights to use, copy, modify, merge, publish, distribute, sublicense, and/or sell copies of the Software, and to permit persons to whom the Software is furnished to do so, subject to the following conditions:

The above copyright notice and this permission notice shall be included in all copies or substantial portions of the Software.

THE SOFTWARE IS PROVIDED “AS IS”, WITHOUT WARRANTY OF ANY KIND, EXPRESS OR IMPLIED, INCLUDING BUT NOT LIMITED TO THE WARRANTIES OF MERCHANTABILITY, FITNESS FOR A PARTICULAR PURPOSE AND NONINFRINGEMENT. IN NO EVENT SHALL THE AUTHORS OR COPYRIGHT HOLDERS BE LIABLE FOR ANY CLAIM, DAMAGES OR OTHER LIABILITY, WHETHER IN AN ACTION OF CONTRACT, TORT OR OTHERWISE, ARISING FROM, OUT OF OR IN CONNECTION WITH THE SOFTWARE OR THE USE OR OTHER DEALINGS IN THE SOFTWARE.
-->
<mujoco model="OpenLoog">
  <compiler angle="radian" meshdir="meshes/"/>
    <option timestep="0.001"  tolerance="1e-10" solver="Newton" jacobian="dense" cone="pyramidal" gravity="0 0 -9.81">  <!--integrator="RK4"  iteration="50"-->
        <flag sensornoise="disable" contact="enable" energy="enable"/>
    </option>
    <size njmax="500" nconmax="1000" />  
    <default>
        <light castshadow="false" />
        <geom rgba="0.784 0.784 0.784 1"/>
        <default class="visual">
            <geom contype="0" conaffinity="0" group="1" type="mesh" euler="1.57 0 0" />
        </default>
        <default class="collision">
            <geom contype="1" conaffinity="1" friction="1.0 0.3 0.3" 
                margin="0.001" group="0" euler="1.57 0 0" />
        </default>
        <joint damping="0.1" frictionloss="0.02" armature="0.01"/>
    </default>
  <asset>
    <mesh name="base_link" file="base_link.STL"/>
    <mesh name="Link_arm_l_01" file="Link_arm_l_01.STL"/>
    <mesh name="Link_arm_l_02" file="Link_arm_l_02.STL"/>
    <mesh name="Link_arm_l_03" file="Link_arm_l_03.STL"/>
    <mesh name="Link_arm_l_04" file="Link_arm_l_04.STL"/>
    <mesh name="Link_arm_l_05" file="Link_arm_l_05.STL"/>
    <mesh name="Link_arm_l_06" file="Link_arm_l_06.STL"/>
    <mesh name="Link_arm_l_07" file="Link_arm_l_07.STL"/>
    <mesh name="Link_arm_r_01" file="Link_arm_r_01.STL"/>
    <mesh name="Link_arm_r_02" file="Link_arm_r_02.STL"/>
    <mesh name="Link_arm_r_03" file="Link_arm_r_03.STL"/>
    <mesh name="Link_arm_r_04" file="Link_arm_r_04.STL"/>
    <mesh name="Link_arm_r_05" file="Link_arm_r_05.STL"/>
    <mesh name="Link_arm_r_06" file="Link_arm_r_06.STL"/>
    <mesh name="Link_arm_r_07" file="Link_arm_r_07.STL"/>
    <mesh name="Link_head_yaw" file="Link_head_yaw.STL"/>
    <mesh name="Link_head_pitch" file="Link_head_pitch.STL"/>
    <mesh name="Link_waist_pitch" file="Link_waist_pitch.STL"/>
    <mesh name="Link_waist_roll" file="Link_waist_roll.STL"/>
    <mesh name="Link_waist_yaw" file="Link_waist_yaw.STL"/>
    <mesh name="Link_hip_l_roll" file="Link_hip_l_roll.STL"/>
    <mesh name="Link_hip_l_yaw" file="Link_hip_l_yaw.STL"/>
    <mesh name="Link_hip_l_pitch" file="Link_hip_l_pitch.STL"/>
    <mesh name="Link_knee_l_pitch" file="Link_knee_l_pitch.STL"/>
    <mesh name="Link_ankle_l_pitch" file="Link_ankle_l_pitch.STL"/>
    <mesh name="Link_ankle_l_roll" file="Link_ankle_l_roll.STL"/>
    <mesh name="Link_hip_r_roll" file="Link_hip_r_roll.STL"/>
    <mesh name="Link_hip_r_yaw" file="Link_hip_r_yaw.STL"/>
    <mesh name="Link_hip_r_pitch" file="Link_hip_r_pitch.STL"/>
    <mesh name="Link_knee_r_pitch" file="Link_knee_r_pitch.STL"/>
    <mesh name="Link_ankle_r_pitch" file="Link_ankle_r_pitch.STL"/>
    <mesh name="Link_ankle_r_roll" file="Link_ankle_r_roll.STL"/>
  </asset>
  <worldbody>
    <!-- <body name="base_link" pos="0 0 1.14" euler="0 0 1.57"> -->
    <body name="base_link" pos="0 0 1.14">
    <freejoint name="float_base"/>
    <inertial  pos="-0.0056641 -0.0013367 0.23829" mass="27" fullinertia="0.4501016 0.3330852 0.2658726 0 0 0" />
    <geom type="mesh" contype="0" conaffinity="0" group="1" density="0" rgba="0.75294 0.75294 0.75294 1" mesh="base_link"/>
    <geom type="mesh" rgba="0.75294 0.75294 0.75294 1" mesh="base_link"/>
    <site name="imu" quat="1 0 0 0"/>
    <body name="Link_arm_l_01" pos="0 0.15585 0.4005">
      <inertial pos="-0.0046426 0.0571151 -3.39e-05" quat="0.444828 0.556229 -0.43726 0.549127" mass="0.99947" diaginertia="0.000911719 0.000823544 0.000749137"/>
      <joint name="J_arm_l_01" pos="0 0 0" axis="0 1 0" limited="true" range="-2.96706 2.96706"/>
      <geom type="mesh" contype="0" conaffinity="0" group="1" density="0" rgba="0.75294 0.75294 0.75294 1" mesh="Link_arm_l_01"/>
      <!-- <geom type="mesh" rgba="0.75294 0.75294 0.75294 1" mesh="Link_arm_l_01"/> -->
      <body name="Link_arm_l_02" pos="0 0.062 0">
        <inertial pos="-0.0010619 0.0788156 -9.4e-06" quat="0.526482 0.472934 -0.525594 0.472125" mass="1.20004" diaginertia="0.002266 0.0018607 0.0012386"/>
        <joint name="J_arm_l_02" pos="0 0 0" axis="1 0 0" limited="true" range="-1.8326 1.8326"/>
        <geom type="mesh" contype="0" conaffinity="0" group="1" density="0" rgba="0.75294 0.75294 0.75294 1" mesh="Link_arm_l_02"/>
        <!-- <geom type="mesh" rgba="0.75294 0.75294 0.75294 1" mesh="Link_arm_l_02"/> -->
        <body name="Link_arm_l_03" pos="0 0.1226 -4.5237e-05">
          <inertial pos="-0.0062837 0.161737 0.020381" quat="0.609073 0.751904 -0.175466 0.181335" mass="1.05028" diaginertia="0.00255348 0.00254657 0.00072375"/>
          <joint name="J_arm_l_03" pos="0 0 0" axis="0 1 0" limited="true" range="-2.96706 2.96706"/>
          <geom type="mesh" contype="0" conaffinity="0" group="1" density="0" rgba="0.75294 0.75294 0.75294 1" mesh="Link_arm_l_03"/>
          <!-- <geom type="mesh" rgba="0.75294 0.75294 0.75294 1" mesh="Link_arm_l_03"/> -->
          <body name="Link_arm_l_04" pos="0 0.1774 0.024">
            <inertial pos="-0.0031896 0.0686669 -0.0204404" quat="0.597368 0.366727 -0.514399 0.494021" mass="0.803908" diaginertia="0.00141739 0.00107318 0.00063653"/>
            <joint name="J_arm_l_04" pos="0 0 0" axis="1 0 0" limited="true" range="0 2.96706"/>
            <geom type="mesh" contype="0" conaffinity="0" group="1" density="0" rgba="0.75294 0.75294 0.75294 1" mesh="Link_arm_l_04"/>
            <!-- <geom type="mesh" rgba="0.75294 0.75294 0.75294 1" mesh="Link_arm_l_04"/> -->
            <body name="Link_arm_l_05" pos="0 0.107 -0.024">
              <inertial pos="-0.0045361 0.0998432 -4e-06" quat="0.700372 0.690476 0.153233 -0.0961354" mass="0.803908" diaginertia="0.00221848 0.00221703 0.000398599"/>
              <joint name="J_arm_l_05" pos="0 0 0" axis="0 1 0" limited="true" range="-2.96706 2.96706"/>
              <geom type="mesh" contype="0" conaffinity="0" group="1" density="0" rgba="0.75294 0.75294 0.75294 1" mesh="Link_arm_l_05"/>
              <!-- <geom type="mesh" rgba="0.75294 0.75294 0.75294 1" mesh="Link_arm_l_05"/> -->
              <body name="Link_arm_l_06" pos="0 0.139 0">
                <inertial pos="-0.000364 0.0482053 0.0065673" quat="0.503552 0.501377 -0.572718 0.408719" mass="0.466149" diaginertia="0.000330806 0.000276112 0.000214481"/>
                <joint name="J_arm_l_06" pos="0 0 0" axis="-1 0 0" limited="true" range="-1.5708 1.5708"/>
                <geom type="mesh" contype="0" conaffinity="0" group="1" density="0" rgba="0.75294 0.75294 0.75294 1" mesh="Link_arm_l_06"/>
                <!-- <geom type="mesh" rgba="0.75294 0.75294 0.75294 1" mesh="Link_arm_l_06"/> -->
                <body name="Link_arm_l_07" pos="0 0.054 4.52e-05">
                  <inertial pos="0.002273 0.103978 0.0019001" quat="0.673353 0.729365 0.0810307 -0.0897653" mass="0.652934" diaginertia="0.00159456 0.00138898 0.000323864"/>
                  <joint name="J_arm_l_07" pos="0 0 0" axis="0 0 1" limited="true" range="-1.309 1.309"/>
                  <geom type="mesh" contype="0" conaffinity="0" group="1" density="0" rgba="0.75294 0.75294 0.75294 1" mesh="Link_arm_l_07"/>
                  <!-- <geom type="mesh" rgba="0.75294 0.75294 0.75294 1" mesh="Link_arm_l_07"/> -->
                </body>
              </body>
            </body>
          </body>
        </body>
      </body>
    </body>
    <body name="Link_arm_r_01" pos="0 -0.15585 0.4005">
      <inertial pos="0.0046514 -0.0571164 -3.39e-05" quat="0.437229 0.5491 -0.444859 0.556256" mass="1.00021" diaginertia="0.000911019 0.000823544 0.000749137"/>
      <joint name="J_arm_r_01" pos="0 0 0" axis="0 -1 0" limited="true" range="-2.96706 2.96706"/>
      <geom type="mesh" contype="0" conaffinity="0" group="1" density="0" rgba="0.75294 0.75294 0.75294 1" mesh="Link_arm_r_01"/>
      <!-- <geom type="mesh" rgba="0.75294 0.75294 0.75294 1" mesh="Link_arm_r_01"/> -->
      <body name="Link_arm_r_02" pos="0 -0.062 0">
        <inertial pos="0.0010619 -0.0788156 -9.4e-06" quat="0.525594 0.472125 -0.526482 0.472934" mass="1.19958" diaginertia="0.002266 0.0018607 0.0012386"/>
        <joint name="J_arm_r_02" pos="0 0 0" axis="-1 0 0" limited="true" range="-1.8326 1.8326"/>
        <geom type="mesh" contype="0" conaffinity="0" group="1" density="0" rgba="0.75294 0.75294 0.75294 1" mesh="Link_arm_r_02"/>
        <!-- <geom type="mesh" rgba="0.75294 0.75294 0.75294 1" mesh="Link_arm_r_02"/> -->
        <body name="Link_arm_r_03" pos="0 -0.1226 -4.5237e-05">
          <inertial pos="0.0062837 -0.161737 0.020381" quat="0.751904 0.609073 0.181335 -0.175466" mass="1.05073" diaginertia="0.00255348 0.00254657 0.00072375"/>
          <joint name="J_arm_r_03" pos="0 0 0" axis="0 -1 0" limited="true" range="-2.96706 2.96706"/>
          <geom type="mesh" contype="0" conaffinity="0" group="1" density="0" rgba="0.75294 0.75294 0.75294 1" mesh="Link_arm_r_03"/>
          <!-- <geom type="mesh" rgba="0.75294 0.75294 0.75294 1" mesh="Link_arm_r_03"/> -->
          <body name="Link_arm_r_04" pos="0 -0.1774 0.024045">
            <inertial pos="0.0031896 -0.0686669 -0.0204404" quat="0.514399 0.494021 -0.597368 0.366727" mass="0.688971" diaginertia="0.00141739 0.00107318 0.00063653"/>
            <joint name="J_arm_r_04" pos="0 0 0" axis="-1 0 0" limited="true" range="0 2.96706"/>
            <geom type="mesh" contype="0" conaffinity="0" group="1" density="0" rgba="0.75294 0.75294 0.75294 1" mesh="Link_arm_r_04"/>
            <!-- <geom type="mesh" rgba="0.75294 0.75294 0.75294 1" mesh="Link_arm_r_04"/> -->
            <body name="Link_arm_r_05" pos="0 -0.107 -0.024045">
              <inertial pos="0.0045361 -0.0998432 -4e-06" quat="0.690465 0.700364 -0.096189 0.153283" mass="0.803908" diaginertia="0.00221847 0.00221703 0.0003985"/>
              <joint name="J_arm_r_05" pos="0 0 0" axis="0 -1 0" limited="true" range="-2.96706 2.96706"/>
              <geom type="mesh" contype="0" conaffinity="0" group="1" density="0" rgba="0.75294 0.75294 0.75294 1" mesh="Link_arm_r_05"/>
              <!-- <geom type="mesh" rgba="0.75294 0.75294 0.75294 1" mesh="Link_arm_r_05"/> -->
              <body name="Link_arm_r_06" pos="0 -0.139 4.5237e-05">
                <inertial pos="0.000364 -0.0482053 0.0065673" quat="0.572584 0.408911 -0.503454 0.501471" mass="0.466149" diaginertia="0.000330804 0.000276207 0.00021439"/>
                <joint name="J_arm_r_06" pos="0 0 0" axis="1 0 0" limited="true" range="-1.5708 1.5708"/>
                <geom type="mesh" contype="0" conaffinity="0" group="1" density="0" rgba="0.75294 0.75294 0.75294 1" mesh="Link_arm_r_06"/>
                <!-- <geom type="mesh" rgba="0.75294 0.75294 0.75294 1" mesh="Link_arm_r_06"/> -->
                <body name="Link_arm_r_07" pos="0 -0.054 0">
                  <inertial pos="0.0028369 -0.10527 0.001581" quat="0.723093 0.672188 0.117633 -0.107061" mass="0.652934" diaginertia="0.00166422 0.00147526 0.000330216"/>
                  <joint name="J_arm_r_07" pos="0 0 0" axis="0 0 1" limited="true" range="-1.309 1.309"/>
                  <geom type="mesh" contype="0" conaffinity="0" group="1" density="0" rgba="0.75294 0.75294 0.75294 1" mesh="Link_arm_r_07"/>
                  <!-- <geom type="mesh" rgba="0.75294 0.75294 0.75294 1" mesh="Link_arm_r_07"/> -->
                </body>
              </body>
            </body>
          </body>
        </body>
      </body>
    </body>
    <body name="Link_head_yaw" pos="0.009 0 0.4064">
      <inertial pos="0 -0.0032217 0.0446573" quat="0.706799 0.0208449 -0.0208449 0.706799" mass="0.84249" diaginertia="0.00068999 0.000595 0.00052001"/>
      <joint name="J_head_yaw" pos="0 0 0" axis="0 0 1" limited="true" range="-1.5708 1.5708"/>
      <geom type="mesh" contype="0" conaffinity="0" group="1" density="0" mesh="Link_head_yaw"/>
      <!-- <geom type="mesh" mesh="Link_head_yaw"/> -->
      <body name="Link_head_pitch" pos="0 -0.0346 0.0485">
        <inertial pos="0.0205621 0.0330045 0.12501" quat="0.971239 0.0144582 -0.227805 -0.0677563" mass="2.65751" diaginertia="0.0121657 0.0119849 0.00854156"/>
        <joint name="J_head_pitch" pos="0 0 0" axis="0 1 0" limited="true" range="-0.7854 0.7854"/>
        <geom type="mesh" contype="0" conaffinity="0" group="1" density="0" mesh="Link_head_pitch"/>
        <!-- <geom type="mesh" mesh="Link_head_pitch"/> -->
      </body>
    </body>
    <body name="Link_waist_pitch" pos="0 -0.0655 0">
      <inertial pos="-0.0011234 0.051969 -4.54e-05" quat="0.449986 0.545249 -0.453 0.543146" mass="3.13477" diaginertia="0.00829606 0.00654164 0.0061531"/>
      <joint name="J_waist_pitch" pos="0 0 0" axis="0 -1 0" limited="true" range="-0.29671 0.7854"/>
      <geom type="mesh" contype="0" conaffinity="0" group="1" density="0"  mesh="Link_waist_pitch"/>
      <!-- <geom type="mesh" mesh="Link_waist_pitch"/> -->
      <body name="Link_waist_roll" pos="-0.064 0.0655 0">
        <inertial pos="-0.0027707 -0.001 -0.0222355" quat="0.376207 0.598722 0.598722 0.376207" mass="3.2" diaginertia="0.0200154 0.0188822 0.00607795"/>
        <joint name="J_waist_roll" pos="0 0 0" axis="1 0 0" limited="true" range="-0.69813 0.69813"/>
        <geom type="mesh" contype="0" conaffinity="0" group="1" density="0" mesh="Link_waist_roll"/>
        <!-- <geom type="mesh"  mesh="Link_waist_roll"/> -->
        <body name="Link_waist_yaw" pos="0.0675 0 -0.098">
          <inertial pos="-0.0954284 -0.001 -0.0572053" quat="0.413409 0.413409 -0.573666 0.573666" mass="7.6" diaginertia="0.11204 0.0917586 0.0338386"/>
          <joint name="J_waist_yaw" pos="0 0 0" axis="0 0 1" limited="true" range="-0.7854 0.7854"/>
          <geom type="mesh" contype="0" conaffinity="0" group="1" density="0" mesh="Link_waist_yaw"/>
          <!-- <geom type="mesh" mesh="Link_waist_yaw"/> -->
          <body name="Link_hip_l_roll" pos="-0.0875 0.12 -0.069">
            <inertial pos="0.075725 -0.00093843 0.016591" quat="0.572176 0.411639 0.40134 0.584888" mass="2.4334" diaginertia="0.00425705 0.00397474 0.0033778"/>
            <joint name="J_hip_l_roll" pos="0 0 0" axis="1 0 0" limited="true" range="-0.17453 0.43633"/>
            <geom type="mesh" contype="0" conaffinity="0" group="1" density="0" mesh="Link_hip_l_roll"/>
            <!-- <geom type="mesh" mesh="Link_hip_l_roll"/> -->
            <body name="Link_hip_l_yaw" pos="0.08225 0 -0.01">
              <inertial pos="-3.1716e-08 0.0071358 -0.10063" quat="0.706536 0.0284018 -0.0284018 0.706536" mass="3.4304" diaginertia="0.0080901 0.0077365 0.0066315"/>
              <joint name="J_hip_l_yaw" pos="0 0 0" axis="0 0 1" limited="true" range="-0.69813 0.69813"/>
              <geom type="mesh" contype="0" conaffinity="0" group="1" density="0" mesh="Link_hip_l_yaw"/>
              <!-- <geom type="mesh" mesh="Link_hip_l_yaw"/> -->
              <body name="Link_hip_l_pitch" pos="0 -0.03675 -0.1055">
                <inertial pos="0.0010856 0.05497 -0.14535" quat="0.999573 -0.0167988 -0.0132685 0.0198712" mass="5.2378" diaginertia="0.0434867 0.0378166 0.0151377"/>
                <joint name="J_hip_l_pitch" pos="0 0 0" axis="0 -1 0" limited="true" range="-0.7854 1.8326"/>
                <geom type="mesh" contype="0" conaffinity="0" group="1" density="0" mesh="Link_hip_l_pitch"/>
                <!-- <geom type="mesh"  mesh="Link_hip_l_pitch"/> -->
                <body name="Link_knee_l_pitch" pos="0 0.01125 -0.4">
                  <inertial pos="-0.0096425 -2.8684e-06 -0.13601" quat="0.762609 -0.016566 -0.000146223 0.646648" mass="2.9775" diaginertia="0.024206 0.0238598 0.00228447"/>
                  <joint name="J_knee_l_pitch" pos="0 0 0" axis="0 -1 0" limited="true" range="-2.35619 0.08727"/>
                  <geom type="mesh" contype="0" conaffinity="0" group="1" density="0" mesh="Link_knee_l_pitch"/>
                  <!-- <geom type="mesh" mesh="Link_knee_l_pitch"/> -->
                  <body name="Link_ankle_l_pitch" pos="0 0 -0.387">
                    <inertial pos="-6.1835e-12 1.2655e-07 6.7022e-08" quat="0.707107 0.707107 0 0" mass="0.10145" diaginertia="2.7175e-05 2.6565e-05 6.1118e-06"/>
                    <joint name="J_ankle_l_pitch" pos="0 0 0" axis="0 -1 0" limited="true" range="-0.47 0.87"/>
                    <geom type="mesh" contype="0" conaffinity="0" group="1" density="0" mesh="Link_ankle_l_pitch"/>
                    <!-- <geom type="mesh" mesh="Link_ankle_l_pitch"/> -->
                    <body name="Link_ankle_l_roll">
                      <inertial pos="0.041077 -2.9318e-08 -0.043909" quat="0 0.735951 0 0.677035" mass="0.752288" diaginertia="0.00365937 0.0036465 0.000416828"/>
                      <joint name="J_ankle_l_roll" pos="0 0 0" axis="1 0 0" limited="true" range="-0.43633 0.43633"/>
                      <geom type="mesh" contype="0" conaffinity="0" group="1" density="0" mesh="Link_ankle_l_roll"/>
                      <!-- <geom type="mesh" mesh="Link_ankle_l_roll"/> -->
                      <geom type="box" rgba="1 0 0 0" pos="0.04749999940395355 0.0012208642475975968 -0.02722398766749333" size="0.1225 0.0402  0.0442 "/>
                      <site name="lf-tc" type="box" size="0.123 0.041  0.045"  pos="0.04749999940395355 0.0012208642475975968 -0.02722398766749333"  rgba="0 1 0 0" />
                    </body>
                  </body>
                </body>
              </body>
            </body>
          </body>
          <body name="Link_hip_r_roll" pos="-0.0875 -0.12 -0.069">
            <inertial pos="0.075725 -0.0010616 0.016591" quat="0.611438 0.357571 0.363289 0.605233" mass="2.4334" diaginertia="0.00450678 0.00399625 0.00360607"/>
            <joint name="J_hip_r_roll" pos="0 0 0" axis="1 0 0" limited="true" range="-0.17453 0.43633"/>
            <geom type="mesh" contype="0" conaffinity="0" group="1" density="0" mesh="Link_hip_r_roll"/>
            <!-- <geom type="mesh" mesh="Link_hip_r_roll"/> -->
            <body name="Link_hip_r_yaw" pos="0.08225 0 -0.01">
              <inertial pos="-3.0911e-08 -0.0071356 -0.10063" quat="0.706536 -0.0284037 0.0284037 0.706536" mass="3.4303" diaginertia="0.0080901 0.0077365 0.0066316"/>
              <joint name="J_hip_r_yaw" pos="0 0 0" axis="0 0 1" limited="true" range="-0.69813 0.69813"/>
              <geom type="mesh" contype="0" conaffinity="0" group="1" density="0" mesh="Link_hip_r_yaw"/>
              <!-- <geom type="mesh" mesh="Link_hip_r_yaw"/> -->
              <body name="Link_hip_r_pitch" pos="0 0.03675 -0.1055">
                <inertial pos="0.0010856 -0.05497 -0.14535" quat="0.999574 0.0167987 -0.0132686 -0.0198624" mass="5.2378" diaginertia="0.0434867 0.0378166 0.0151377"/>
                <joint name="J_hip_r_pitch" pos="0 0 0" axis="0 -1 0" limited="true" range="-0.7854 1.8326"/>
                <geom type="mesh" contype="0" conaffinity="0" group="1" density="0" mesh="Link_hip_r_pitch"/>
                <!-- <geom type="mesh" mesh="Link_hip_r_pitch"/> -->
                <body name="Link_knee_r_pitch" pos="0 -0.01125 -0.4">
                  <inertial pos="-0.0096425 2.9338e-06 -0.13601" quat="0.646651 -0.000144685 -0.016567 0.762606" mass="2.9775" diaginertia="0.024207 0.0238608 0.00228446"/>
                  <joint name="J_knee_r_pitch" pos="0 0 0" axis="0 -1 0" limited="true" range="-2.35619 0.08727"/>
                  <geom type="mesh" contype="0" conaffinity="0" group="1" density="0" mesh="Link_knee_r_pitch"/>
                  <!-- <geom type="mesh" mesh="Link_knee_r_pitch"/> -->
                  <body name="Link_ankle_r_pitch" pos="0 0 -0.387">
                    <inertial pos="-6.1835e-12 -1.2655e-07 -2.4682e-08" quat="0.707107 0.707107 0 0" mass="0.10145" diaginertia="2.7175e-05 2.6565e-05 6.1118e-06"/>
                    <joint name="J_ankle_r_pitch" pos="0 0 0" axis="0 -1 0" limited="true" range="-0.47 0.87"/>
                    <geom type="mesh" contype="0" conaffinity="0" group="1" density="0" mesh="Link_ankle_r_pitch"/>
                    <!-- <geom type="mesh" mesh="Link_ankle_r_pitch"/> -->
                    <body name="Link_ankle_r_roll">
                      <inertial pos="0.041078 -8.9152e-08 -0.043909" quat="0 0.735951 0 0.677035" mass="0.75229" diaginertia="0.00365937 0.0036465 0.000416828"/>
                      <joint name="J_ankle_r_roll" pos="0 0 0" axis="1 0 0" limited="true" range="-0.43633 0.43633"/>
                      <geom type="mesh" contype="0" conaffinity="0" group="1" density="0" mesh="Link_ankle_r_roll"/>
                      <!-- <geom type="mesh" mesh="Link_ankle_r_roll"/> -->
                      <geom type="box" rgba="1 0 0 0" pos="0.04750461363863139 8.266688098764184e-05 -0.02654531035541249" size="0.1225  0.0400  0.0435 "  />
                      <site name="rf-tc" type="box" size="0.123  0.041   0.044" pos="0.04750461363863139 8.266688098764184e-05 -0.02654531035541249" rgba="0 1 0 0" />
                    </body>
                  </body>
                </body>
              </body>
            </body>
          </body>
        </body>
      </body>
    </body>
  </body>
  </worldbody>
  <contact>
      <exclude name="ex_baselink_waist_pitch" body1="base_link" body2="Link_waist_pitch" />
      <exclude name="ex_waist_pitch_waist_roll" body1="Link_waist_pitch" body2="Link_waist_roll" />
      <exclude name="ex_waist_roll_waist_yaw" body1="Link_waist_roll" body2="Link_waist_yaw" />

      <exclude name="ex_waist_yaw_l_hip_roll" body1="Link_waist_yaw" body2="Link_hip_l_roll" /> 
      <exclude name="ex_l_hip_roll_hip_yaw" body1="Link_hip_l_roll" body2="Link_hip_l_yaw" /> 
      <exclude name="ex_l_hip_yaw_hip_pitch" body1="Link_hip_l_yaw" body2="Link_hip_l_pitch" /> 
      <exclude name="ex_l_hip_pitch_knee_pitch" body1="Link_hip_l_pitch" body2="Link_knee_l_pitch" /> 
      <exclude name="ex_l_knee_pitch_ankle_pitch" body1="Link_knee_l_pitch" body2="Link_ankle_l_pitch" />
      <exclude name="ex_l_ankle_pitch_ankle_roll" body1="Link_ankle_l_pitch" body2="Link_ankle_l_roll" />

      <exclude name="ex_waist_yaw_r_hip_roll" body1="Link_waist_yaw" body2="Link_hip_r_roll" />    	
      <exclude name="ex_r_hip_roll_hip_yaw" body1="Link_hip_r_roll" body2="Link_hip_r_yaw" /> 
      <exclude name="ex_r_hip_yaw_hip_pitch" body1="Link_hip_r_yaw" body2="Link_hip_r_pitch" /> 
      <exclude name="ex_r_hip_pitch_knee_pitch" body1="Link_hip_r_pitch" body2="Link_knee_r_pitch" /> 
      <exclude name="ex_r_knee_pitch_ankle_pitch" body1="Link_knee_r_pitch" body2="Link_ankle_r_pitch" />
      <exclude name="ex_r_ankle_pitch_ankle_roll" body1="Link_ankle_r_pitch" body2="Link_ankle_r_roll" />

      <exclude name="ex_baselink_l_arm_01" body1="base_link" body2="Link_arm_l_01" />
      <exclude name="ex_l_arm_01_arm_02" body1="Link_arm_l_01" body2="Link_arm_l_02" />
      <exclude name="ex_l_arm_02_arm_03" body1="Link_arm_l_02" body2="Link_arm_l_03" />         
      <exclude name="ex_l_arm_03_arm_04" body1="Link_arm_l_03" body2="Link_arm_l_04" />
      <exclude name="ex_l_arm_04_arm_05" body1="Link_arm_l_04" body2="Link_arm_l_05" />
      <exclude name="ex_l_arm_05_arm_06" body1="Link_arm_l_05" body2="Link_arm_l_06" />
      <exclude name="ex_l_arm_06_arm_07" body1="Link_arm_l_06" body2="Link_arm_l_07" />    

      <exclude name="ex_baselink_r_arm_01" body1="base_link" body2="Link_arm_r_01" />
      <exclude name="ex_r_arm_01_arm_02" body1="Link_arm_r_01" body2="Link_arm_r_02" />
      <exclude name="ex_r_arm_02_arm_03" body1="Link_arm_r_02" body2="Link_arm_r_03" />         
      <exclude name="ex_r_arm_03_arm_04" body1="Link_arm_r_03" body2="Link_arm_r_04" />
      <exclude name="ex_r_arm_04_arm_05" body1="Link_arm_r_04" body2="Link_arm_r_05" />
      <exclude name="ex_r_arm_05_arm_06" body1="Link_arm_r_05" body2="Link_arm_r_06" />
      <exclude name="ex_r_arm_06_arm_07" body1="Link_arm_r_06" body2="Link_arm_r_07" />  
  
      <exclude name="ex_baselink_head_yaw" body1="base_link" body2="Link_head_yaw" />
      <exclude name="ex_head_yaw_pitch" body1="Link_head_yaw" body2="Link_head_pitch" />
      <exclude name="ex_baselink_head_pitch" body1="base_link" body2="Link_head_pitch" />

      <exclude name="ex_waist_yaw_l_hip_pitch" body1="Link_waist_yaw" body2="Link_hip_l_pitch" />           				     
      <exclude name="ex_waist_yaw_r_hip_pitch" body1="Link_waist_yaw" body2="Link_hip_r_pitch" />        
      <exclude name="ex_baselink_waist_roll" body1="base_link" body2="Link_waist_roll" />

      <exclude name="ex_l_knee_pitch_ankle_roll" body1="Link_knee_l_pitch" body2="Link_ankle_l_roll" />
      <exclude name="ex_r_knee_pitch_ankle_roll" body1="Link_knee_r_pitch" body2="Link_ankle_r_roll" />

      <exclude name="ex_l_arm_05_arm_07" body1="Link_arm_l_05" body2="Link_arm_l_07" />        
      <exclude name="ex_r_arm_05_arm_07" body1="Link_arm_r_05" body2="Link_arm_r_07" />   

      <exclude name="ex_waist_yaw_l_hip_yaw" body1="Link_waist_yaw" body2="Link_hip_l_yaw" />
      <exclude name="ex_waist_yaw_r_hip_yaw" body1="Link_waist_yaw" body2="Link_hip_r_yaw" />
        
  </contact>
  <actuator>
      <motor name="M_arm_l_01"  joint="J_arm_l_01" gear="1" ctrllimited="true" ctrlrange="-80 80"/>
      <motor name="M_arm_l_02"  joint="J_arm_l_02" gear="1" ctrllimited="true" ctrlrange="-80 80"/>
      <motor name="M_arm_l_03"  joint="J_arm_l_03" gear="1" ctrllimited="true" ctrlrange="-48 48"/>
      <motor name="M_arm_l_04"  joint="J_arm_l_04" gear="1" ctrllimited="true" ctrlrange="-48 48"/>
      <motor name="M_arm_l_05"  joint="J_arm_l_05" gear="1" ctrllimited="true" ctrlrange="-12.4 12.4"/>
      <motor name="M_arm_l_06"  joint="J_arm_l_06" gear="1" ctrllimited="true" ctrlrange="-12.4 12.4"/>
      <motor name="M_arm_l_07"  joint="J_arm_l_07" gear="1" ctrllimited="true" ctrlrange="-12.4 12.4"/>

      <motor name="M_arm_r_01"  joint="J_arm_r_01" gear="1" ctrllimited="true" ctrlrange="-80 80"/>
      <motor name="M_arm_r_02"  joint="J_arm_r_02" gear="1" ctrllimited="true" ctrlrange="-80 80"/>
      <motor name="M_arm_r_03"  joint="J_arm_r_03" gear="1" ctrllimited="true" ctrlrange="-48 48"/>
      <motor name="M_arm_r_04"  joint="J_arm_r_04" gear="1" ctrllimited="true" ctrlrange="-48 48"/>
      <motor name="M_arm_r_05"  joint="J_arm_r_05" gear="1" ctrllimited="true" ctrlrange="-12.4 12.4"/>
      <motor name="M_arm_r_06"  joint="J_arm_r_06" gear="1" ctrllimited="true" ctrlrange="-12.4 12.4"/>
      <motor name="M_arm_r_07"  joint="J_arm_r_07" gear="1" ctrllimited="true" ctrlrange="-12.4 12.4"/>

      <motor name="M_head_yaw"  joint="J_head_yaw" gear="1" ctrllimited="true" ctrlrange="-26 26"/>
      <motor name="M_head_pitch"  joint="J_head_pitch" gear="1" ctrllimited="true" ctrlrange="-26 26"/>

      <motor name="M_waist_pitch"  joint="J_waist_pitch" gear="1" ctrllimited="true" ctrlrange="-315 315"/>
      <motor name="M_waist_roll"  joint="J_waist_roll" gear="1" ctrllimited="true" ctrlrange="-315 315"/>
      <motor name="M_waist_yaw"  joint="J_waist_yaw" gear="1" ctrllimited="true" ctrlrange="-121 121"/>

      <motor name="M_hip_l_roll"  joint="J_hip_l_roll" gear="1" ctrllimited="true" ctrlrange="-320 320"/>
      <motor name="M_hip_l_yaw"  joint="J_hip_l_yaw" gear="1" ctrllimited="true" ctrlrange="-160 160"/>
      <motor name="M_hip_l_pitch" joint="J_hip_l_pitch" gear="1" ctrllimited="true" ctrlrange="-396 396"/>
      <motor name="M_knee_l_pitch"  joint="J_knee_l_pitch" gear="1" ctrllimited="true" ctrlrange="-396 396"/>
      <motor name="M_ankle_l_pitch"  joint="J_ankle_l_pitch" gear="1" ctrllimited="true" ctrlrange="-58.5 58.5"/>
      <motor name="M_ankle_l_roll"  joint="J_ankle_l_roll" gear="1" ctrllimited="true" ctrlrange="-58.5 58.5"/>

      <motor name="M_hip_r_roll"  joint="J_hip_r_roll" gear="1" ctrllimited="true" ctrlrange="-320 320"/>
      <motor name="M_hip_r_yaw"  joint="J_hip_r_yaw" gear="1" ctrllimited="true" ctrlrange="-160 160"/>
      <motor name="M_hip_r_pitch"  joint="J_hip_r_pitch" gear="1" ctrllimited="true" ctrlrange="-396 396"/>
      <motor name="M_knee_r_pitch"  joint="J_knee_r_pitch" gear="1" ctrllimited="true" ctrlrange="-396 396"/>
      <motor name="M_ankle_r_pitch"  joint="J_ankle_r_pitch" gear="1" ctrllimited="true" ctrlrange="-58.5 58.5"/>
      <motor name="M_ankle_r_roll"  joint="J_ankle_r_roll" gear="1" ctrllimited="true" ctrlrange="-58.5 58.5"/>
  </actuator>

  
  <sensor>
      <framequat name="baselink-quat" objtype="site" objname="imu" />
      <velocimeter name="baselink-velocity" site="imu" />
      <gyro name="baselink-gyro" site="imu" />
      <accelerometer name="baselink-baseAcc" site="imu" />
      <touch name="lf-touch" site="lf-tc" />
      <touch name="rf-touch" site="rf-tc" />
  </sensor>

</mujoco>