<?xml version="1.0" encoding="utf-8"?>
<!-- This URDF was automatically created by SolidWorks to URDF Exporter! Originally created by Stephen Brawner (brawner@gmail.com) 
     Commit Version: 1.6.0-4-g7f85cfe  Build Version: 1.6.7995.38578
     For more information, please see http://wiki.ros.org/sw_urdf_exporter -->
<!-- 
Copyright 2025 国地共建人形机器人创新中心/人形机器人（上海）有限公司, https://www.openloong.net/

Permission is hereby granted, free of charge, to any person obtaining a copy of this software and associated documentation files (the “Software”), to deal in the Software without restriction, including without limitation the rights to use, copy, modify, merge, publish, distribute, sublicense, and/or sell copies of the Software, and to permit persons to whom the Software is furnished to do so, subject to the following conditions:

The above copyright notice and this permission notice shall be included in all copies or substantial portions of the Software.

THE SOFTWARE IS PROVIDED “AS IS”, WITHOUT WARRANTY OF ANY KIND, EXPRESS OR IMPLIED, INCLUDING BUT NOT LIMITED TO THE WARRANTIES OF MERCHANTABILITY, FITNESS FOR A PARTICULAR PURPOSE AND NONINFRINGEMENT. IN NO EVENT SHALL THE AUTHORS OR COPYRIGHT HOLDERS BE LIABLE FOR ANY CLAIM, DAMAGES OR OTHER LIABILITY, WHETHER IN AN ACTION OF CONTRACT, TORT OR OTHERWISE, ARISING FROM, OUT OF OR IN CONNECTION WITH THE SOFTWARE OR THE USE OR OTHER DEALINGS IN THE SOFTWARE.
-->
<robot
  name="OpenLoog">
  <mujoco>
    <compiler
    	meshdir="meshes/"
    	balanceinertia="true"
    	discardvisual="false" />
  </mujoco>
  <link
    name="base_link">
    <inertial>
      <origin
        xyz="-0.0056641 -0.0013367 0.23829"
        rpy="0 0 0" />
      <mass
        value="22.447" />
      <inertia
        ixx="0.3742"
        ixy="0"
        ixz="0"
        iyy="0.27691"
        iyz="0"
        izz="0.22104" />
    </inertial>
    <visual>
      <origin
        xyz="0 0 0"
        rpy="0 0 0" />
      <geometry>
        <mesh
          filename="package://AzureLoong/meshes/base_link.STL" />
      </geometry>
      <material
        name="">
        <color
          rgba="0.75294 0.75294 0.75294 1" />
      </material>
    </visual>
    <collision>
      <origin
        xyz="0 0 0"
        rpy="0 0 0" />
      <geometry>
        <mesh
          filename="package://AzureLoong/meshes/base_link.STL" />
      </geometry>
    </collision>
  </link>
  <!-- <link
    name="Link_head_yaw">
    <inertial>
      <origin
        xyz="4.6974E-12 -0.0020814 0.044801"
        rpy="0 0 0" />
      <mass
        value="0.84249" />
      <inertia
        ixx="0.000629"
        ixy="-1.2848E-14"
        ixz="1.5461E-10"
        iyy="0.0007003"
        iyz="6.5E-06"
        izz="0.0005541" />
    </inertial>
    <visual>
      <origin
        xyz="0 0 0"
        rpy="0 0 0" />
      <geometry>
        <mesh
          filename="package://AzureDragon/meshes/Link_head_yaw.STL" />
      </geometry>
      <material
        name="">
        <color
          rgba="0.89804 0.91765 0.92941 1" />
      </material>
    </visual>
    <collision>
      <origin
        xyz="0 0 0"
        rpy="0 0 0" />
      <geometry>
        <mesh
          filename="package://AzureDragon/meshes/Link_head_yaw.STL" />
      </geometry>
    </collision>
  </link>
  <joint
    name="J_head_yaw"
    type="revolute">
    <origin
      xyz="0.009 0 0.4064"
      rpy="0 0 0" />
    <parent
      link="base_link" />
    <child
      link="Link_head_yaw" />
    <axis
      xyz="0 0 1" />
    <limit
      lower="-1.5708"
      upper="1.5708"
      effort="26"
      velocity="109.8" />
  </joint>
  <link
    name="Link_head_pitch">
    <inertial>
      <origin
        xyz="0.020569 0.033004 0.125"
        rpy="0 0 0" />
      <mass
        value="1.3943" />
      <inertia
        ixx="0.0060059"
        ixy="-9.4E-06"
        ixz="0.0007564"
        iyy="0.00629"
        iyz="-1.03E-05"
        izz="0.0048569" />
    </inertial>
    <visual>
      <origin
        xyz="0 0 0"
        rpy="0 0 0" />
      <geometry>
        <mesh
          filename="package://AzureDragon/meshes/Link_head_pitch.STL" />
      </geometry>
      <material
        name="">
        <color
          rgba="0.69804 0.69804 0.69804 1" />
      </material>
    </visual>
    <collision>
      <origin
        xyz="0 0 0"
        rpy="0 0 0" />
      <geometry>
        <mesh
          filename="package://AzureDragon/meshes/Link_head_pitch.STL" />
      </geometry>
    </collision>
  </link>
  <joint
    name="J_head_pitch"
    type="revolute">
    <origin
      xyz="0 -0.0345999999999997 0.0484999999999999"
      rpy="0 0 0" />
    <parent
      link="Link_head_yaw" />
    <child
      link="Link_head_pitch" />
    <axis
      xyz="0 -1 0" />
    <limit
      lower="-0.7854"
      upper="0.7854"
      effort="26"
      velocity="109.8" />
  </joint> -->
  <link
    name="Link_arm_r_01">
    <inertial>
      <origin
        xyz="0.0044946 0.002706 -1.8744E-06"
        rpy="0 0 0" />
      <mass
        value="0.75641" />
      <inertia
        ixx="0.00058712"
        ixy="2.9803E-07"
        ixz="5.8378E-09"
        iyy="0.00080305"
        iyz="-3.6648E-08"
        izz="0.00084299" />
    </inertial>
    <visual>
      <origin
        xyz="0 0.041 0"
        rpy="0 0 0" />
      <geometry>
        <mesh
          filename="package://AzureLoong/meshes/Link_arm_r_01.STL" />
      </geometry>
      <material
        name="">
        <color
          rgba="0.69804 0.69804 0.69804 1" />
      </material>
    </visual>
    <collision>
      <origin
        xyz="0 0.041 0"
        rpy="0 0 0" />
      <geometry>
        <mesh
          filename="package://AzureLoong/meshes/Link_arm_r_01.STL" />
      </geometry>
    </collision>
  </link>
  <joint
    name="J_arm_r_01"
    type="revolute">
    <origin
      xyz="0.004 -0.2026 0.3922"
      rpy="0 0 0" />
    <parent
      link="base_link" />
    <child
      link="Link_arm_r_01" />
    <axis
      xyz="0 -1 0" />
    <limit
      lower="-2.96706"
      upper="2.96706"
      effort="80"
      velocity="3.14" />
  </joint>
  <link
    name="Link_arm_r_02">
    <inertial>
      <origin
        xyz="0 -0.0674307499121858 -6.93889390390723E-18"
        rpy="0 0 0" />
      <mass
        value="0.984999996273518" />
      <inertia
        ixx="0.0017309882399251"
        ixy="-9.79515256436727E-20"
        ixz="-3.63988309726277E-19"
        iyy="0.00115401958000568"
        iyz="4.42134220053852E-19"
        izz="0.00226269324370836" />
    </inertial>
    <visual>
      <origin
        xyz="-0.042 0 0"
        rpy="0 0 0" />
      <geometry>
        <mesh
          filename="package://AzureLoong/meshes/Link_arm_r_02.STL" />
      </geometry>
      <material
        name="">
        <color
          rgba="0.698039215686274 0.698039215686274 0.698039215686274 1" />
      </material>
    </visual>
    <collision>
      <origin
        xyz="-0.042 0 0"
        rpy="0 0 0" />
      <geometry>
        <mesh
          filename="package://AzureLoong/meshes/Link_arm_r_02.STL" />
      </geometry>
    </collision>
  </link>
  <joint
    name="J_arm_r_02"
    type="revolute">
    <origin
      xyz="0 0 0"
      rpy="0 0 0" />
    <parent
      link="Link_arm_r_01" />
    <child
      link="Link_arm_r_02" />
    <axis
      xyz="-1 0 0" />
    <limit
      lower="-1.83260"
      upper="1.83260"
      effort="80"
      velocity="3.14" />
  </joint>
  <link
    name="Link_arm_r_03">
    <inertial>
      <origin
        xyz="-0.00141357502419955 -0.164662742175383 0.0207578924800774"
        rpy="0 0 0" />
      <mass
        value="0.958999855228924" />
      <inertia
        ixx="0.00206438134078715"
        ixy="1.82014067823509E-05"
        ixz="-5.1283136963991E-06"
        iyy="0.00080535412926664"
        iyz="-0.000255265992194607"
        izz="0.00205099914609259" />
    </inertial>
    <visual>
      <origin
        xyz="0 0 0"
        rpy="0 0 0" />
      <geometry>
        <mesh
          filename="package://AzureLoong/meshes/Link_arm_r_03.STL" />
      </geometry>
      <material
        name="">
        <color
          rgba="0.698039215686274 0.698039215686274 0.698039215686274 1" />
      </material>
    </visual>
    <collision>
      <origin
        xyz="0 0 0"
        rpy="0 0 0" />
      <geometry>
        <mesh
          filename="package://AzureLoong/meshes/Link_arm_r_03.STL" />
      </geometry>
    </collision>
  </link>
  <joint
    name="J_arm_r_03"
    type="revolute">
    <origin
      xyz="0 -0.1226 0"
      rpy="0 0 0" />
    <parent
      link="Link_arm_r_02" />
    <child
      link="Link_arm_r_03" />
    <axis
      xyz="0 -1 0" />
    <limit
      lower="-2.96706"
      upper="2.96706"
      effort="48"
      velocity="3.14" />
  </joint>
  <link
    name="Link_arm_r_04">
    <inertial>
      <origin
        xyz="-0.0034 -0.060767 -0.021003"
        rpy="0 0 0" />
      <mass
        value="0.6" />
      <inertia
        ixx="0.00070398"
        ixy="-2.023E-05"
        ixz="-1.1263E-05"
        iyy="0.00068085"
        iyz="0.00010585"
        izz="0.0010653" />
    </inertial>
    <visual>
      <origin
        xyz="0.0353 0 0"
        rpy="0 0 0" />
      <geometry>
        <mesh
          filename="package://AzureLoong/meshes/Link_arm_r_04.STL" />
      </geometry>
      <material
        name="">
        <color
          rgba="0.69804 0.69804 0.69804 1" />
      </material>
    </visual>
    <collision>
      <origin
        xyz="0.0353 0 0"
        rpy="0 0 0" />
      <geometry>
        <mesh
          filename="package://AzureLoong/meshes/Link_arm_r_04.STL" />
      </geometry>
    </collision>
  </link>
  <joint
    name="J_arm_r_04"
    type="revolute">
    <origin
      xyz="0 -0.1774 0.024"
      rpy="0 0 0" />
    <parent
      link="Link_arm_r_03" />
    <child
      link="Link_arm_r_04" />
    <axis
      xyz="-1 0 0" />
    <limit
      lower="0"
      upper="2.96706"
      effort="48"
      velocity="3.14" />
  </joint>
  <link
    name="Link_arm_r_05">
    <inertial>
      <origin
        xyz="3.2712E-05 -0.068658 -0.00011178"
        rpy="0 0 0" />
      <mass
        value="0.68976" />
      <inertia
        ixx="0.0025225"
        ixy="4E-07"
        ixz="-8E-07"
        iyy="0.0004487"
        iyz="-3.1E-06"
        izz="0.0024111" />
    </inertial>
    <visual>
      <origin
        xyz="0 0 0"
        rpy="0 0 0" />
      <geometry>
        <mesh
          filename="package://AzureLoong/meshes/Link_arm_r_05.STL" />
      </geometry>
      <material
        name="">
        <color
          rgba="0.69804 0.69804 0.69804 1" />
      </material>
    </visual>
    <collision>
      <origin
        xyz="0 0 0"
        rpy="0 0 0" />
      <geometry>
        <mesh
          filename="package://AzureLoong/meshes/Link_arm_r_05.STL" />
      </geometry>
    </collision>
  </link>
  <joint
    name="J_arm_r_05"
    type="revolute">
    <origin
      xyz="0 -0.1035 -0.024"
      rpy="0 0 0" />
    <parent
      link="Link_arm_r_04" />
    <child
      link="Link_arm_r_05" />
    <axis
      xyz="0 -1 0" />
    <limit
      lower="-2.96706"
      upper="2.96706"
      effort="12.4"
      velocity="6.28" />
  </joint>
  <link
    name="Link_arm_r_06">
    <inertial>
      <origin
        xyz="0 -8.9588E-07 0.0016637"
        rpy="0 0 0" />
      <mass
        value="0.28" />
      <inertia
        ixx="0.0001456"
        ixy="7.7026E-10"
        ixz="2.1456E-07"
        iyy="0.00015693"
        iyz="2.4102E-09"
        izz="0.00010498" />
    </inertial>
    <visual>
      <origin
        xyz="-0.0265 0 0"
        rpy="0 0 0" />
      <geometry>
        <mesh
          filename="package://AzureLoong/meshes/Link_arm_r_06.STL" />
      </geometry>
      <material
        name="">
        <color
          rgba="0.69804 0.69804 0.69804 1" />
      </material>
    </visual>
    <collision>
      <origin
        xyz="-0.0265 0 0"
        rpy="0 0 0" />
      <geometry>
        <mesh
          filename="package://AzureLoong/meshes/Link_arm_r_06.STL" />
      </geometry>
    </collision>
  </link>
  <joint
    name="J_arm_r_06"
    type="revolute">
    <origin
      xyz="0 -0.1965 0"
      rpy="0 0 0" />
    <parent
      link="Link_arm_r_05" />
    <child
      link="Link_arm_r_06" />
    <axis
      xyz="1 0 0" />
    <limit
      lower="-1.8326"
      upper="1.8326"
      effort="12.4"
      velocity="6.28" />
  </joint>
  <link
    name="Link_arm_r_07">
    <inertial>
      <origin
        xyz="-0.007859 -0.15817 0.00406"
        rpy="0 0 0" />
      <mass
        value="0.61354" />
      <inertia
        ixx="0.0025969"
        ixy="-4.65E-05"
        ixz="0.0001089"
        iyy="0.0007306"
        iyz="1.47E-05"
        izz="0.0030104" />
    </inertial>
    <visual>
      <origin
        xyz="0 0 0.0318"
        rpy="0 0 0" />
      <geometry>
        <mesh
          filename="package://AzureLoong/meshes/Link_arm_r_07.STL" />
      </geometry>
      <material
        name="">
        <color
          rgba="0.77647 0.75686 0.73725 1" />
      </material>
    </visual>
    <collision>
      <origin
        xyz="0 0 0.0318"
        rpy="0 0 0" />
      <geometry>
        <mesh
          filename="package://AzureLoong/meshes/Link_arm_r_07.STL" />
      </geometry>
    </collision>
  </link>
  <joint
    name="J_arm_r_07"
    type="revolute">
    <origin
      xyz="0 0 0"
      rpy="0 0 0" />
    <parent
      link="Link_arm_r_06" />
    <child
      link="Link_arm_r_07" />
    <axis
      xyz="0 0 1" />
    <limit
      lower="-1.04720"
      upper="1.04720"
      effort="12.4"
      velocity="6.28" />
  </joint>
  <link
    name="Link_arm_l_01">
    <inertial>
      <origin
        xyz="-0.00449464987882542 -0.0027 -1.874402432607E-06"
        rpy="0 0 0" />
      <mass
        value="0.756406339732892" />
      <inertia
        ixx="0.000587115683146372"
        ixy="2.98026052651538E-07"
        ixz="-5.83781087215966E-09"
        iyy="0.000803052813361661"
        iyz="3.66476835396106E-08"
        izz="0.000842985653484675" />
    </inertial>
    <visual>
      <origin
        xyz="0 -0.041 0"
        rpy="0 0 0" />
      <geometry>
        <mesh
          filename="package://AzureLoong/meshes/Link_arm_l_01.STL" />
      </geometry>
      <material
        name="">
        <color
          rgba="0.698039215686274 0.698039215686274 0.698039215686274 1" />
      </material>
    </visual>
    <collision>
      <origin
        xyz="0 -0.041 0"
        rpy="0 0 0" />
      <geometry>
        <mesh
          filename="package://AzureLoong/meshes/Link_arm_l_01.STL" />
      </geometry>
    </collision>
  </link>
  <joint
    name="J_arm_l_01"
    type="revolute">
    <origin
      xyz="0.004 0.2026 0.3922"
      rpy="0 0 0" />
    <parent
      link="base_link" />
    <child
      link="Link_arm_l_01" />
    <axis
      xyz="0 1 0" />
    <limit
      lower="-2.96706"
      upper="2.96706"
      effort="80"
      velocity="3.14" />
  </joint>
  <link
    name="Link_arm_l_02">
    <inertial>
      <origin
        xyz="0 0.0674307499121858 1.38777878078145E-17"
        rpy="0 0 0" />
      <mass
        value="0.984999996273518" />
      <inertia
        ixx="0.0017309882399251"
        ixy="-1.48322871384691E-19"
        ixz="-1.94588987195478E-19"
        iyy="0.00115401958000568"
        iyz="-6.15989345249147E-19"
        izz="0.00226269324370836" />
    </inertial>
    <visual>
      <origin
        xyz="0.042 0 0"
        rpy="0 0 0" />
      <geometry>
        <mesh
          filename="package://AzureLoong/meshes/Link_arm_l_02.STL" />
      </geometry>
      <material
        name="">
        <color
          rgba="0.698039215686274 0.698039215686274 0.698039215686274 1" />
      </material>
    </visual>
    <collision>
      <origin
        xyz="0.042 0 0"
        rpy="0 0 0" />
      <geometry>
        <mesh
          filename="package://AzureLoong/meshes/Link_arm_l_02.STL" />
      </geometry>
    </collision>
  </link>
  <joint
    name="J_arm_l_02"
    type="revolute">
    <origin
      xyz="0 0 0"
      rpy="0 0 0" />
    <parent
      link="Link_arm_l_01" />
    <child
      link="Link_arm_l_02" />
    <axis
      xyz="1 0 0" />
    <limit
      lower="-1.83260"
      upper="1.83260"
      effort="80"
      velocity="3.14" />
  </joint>
  <link
    name="Link_arm_l_03">
    <inertial>
      <origin
        xyz="0.00141357502419956 0.164662742175383 0.0207578924800774"
        rpy="0 0 0" />
      <mass
        value="0.958999855228925" />
      <inertia
        ixx="0.00206438134078715"
        ixy="1.82014067823508E-05"
        ixz="5.12831369639908E-06"
        iyy="0.000805354129266641"
        iyz="0.000255265992194607"
        izz="0.00205099914609259" />
    </inertial>
    <visual>
      <origin
        xyz="0 0 0"
        rpy="0 0 0" />
      <geometry>
        <mesh
          filename="package://AzureLoong/meshes/Link_arm_l_03.STL" />
      </geometry>
      <material
        name="">
        <color
          rgba="0.698039215686274 0.698039215686274 0.698039215686274 1" />
      </material>
    </visual>
    <collision>
      <origin
        xyz="0 0 0"
        rpy="0 0 0" />
      <geometry>
        <mesh
          filename="package://AzureLoong/meshes/Link_arm_l_03.STL" />
      </geometry>
    </collision>
  </link>
  <joint
    name="J_arm_l_03"
    type="revolute">
    <origin
      xyz="0 0.1226 0"
      rpy="0 0 0" />
    <parent
      link="Link_arm_l_02" />
    <child
      link="Link_arm_l_03" />
    <axis
      xyz="0 1 0" />
    <limit
      lower="-2.96706"
      upper="2.96706"
      effort="48"
      velocity="3.14" />
  </joint>
  <link
    name="Link_arm_l_04">
    <inertial>
      <origin
        xyz="0.0034 0.0607672244593032 -0.0210032450980798"
        rpy="0 0 0" />
      <mass
        value="0.60000012303258" />
      <inertia
        ixx="0.000703976141425558"
        ixy="-2.02301178076816E-05"
        ixz="1.12633779930363E-05"
        iyy="0.000680850033983237"
        iyz="-0.000105852227353173"
        izz="0.00106526266740194" />
    </inertial>
    <visual>
      <origin
        xyz="-0.0353 0 0"
        rpy="0 0 0" />
      <geometry>
        <mesh
          filename="package://AzureLoong/meshes/Link_arm_l_04.STL" />
      </geometry>
      <material
        name="">
        <color
          rgba="0.698039215686274 0.698039215686274 0.698039215686274 1" />
      </material>
    </visual>
    <collision>
      <origin
        xyz="-0.0353 0 0"
        rpy="0 0 0" />
      <geometry>
        <mesh
          filename="package://AzureLoong/meshes/Link_arm_l_04.STL" />
      </geometry>
    </collision>
  </link>
  <joint
    name="J_arm_l_04"
    type="revolute">
    <origin
      xyz="0 0.1774 0.024"
      rpy="0 0 0" />
    <parent
      link="Link_arm_l_03" />
    <child
      link="Link_arm_l_04" />
    <axis
      xyz="1 0 0" />
    <limit
      lower="0"
      upper="2.96706"
      effort="48"
      velocity="3.14" />
  </joint>
  <link
    name="Link_arm_l_05">
    <inertial>
      <origin
        xyz="-3.2712E-05 0.068658 -0.00011178"
        rpy="0 0 0" />
      <mass
        value="0.68976" />
      <inertia
        ixx="0.0025225"
        ixy="4E-07"
        ixz="8E-07"
        iyy="0.0004487"
        iyz="3.1E-06"
        izz="0.0024111" />
    </inertial>
    <visual>
      <origin
        xyz="0 0 0"
        rpy="0 0 0" />
      <geometry>
        <mesh
          filename="package://AzureLoong/meshes/Link_arm_l_05.STL" />
      </geometry>
      <material
        name="">
        <color
          rgba="0.69804 0.69804 0.69804 1" />
      </material>
    </visual>
    <collision>
      <origin
        xyz="0 0 0"
        rpy="0 0 0" />
      <geometry>
        <mesh
          filename="package://AzureLoong/meshes/Link_arm_l_05.STL" />
      </geometry>
    </collision>
  </link>
  <joint
    name="J_arm_l_05"
    type="revolute">
    <origin
      xyz="0 0.1035 -0.024"
      rpy="0 0 0" />
    <parent
      link="Link_arm_l_04" />
    <child
      link="Link_arm_l_05" />
    <axis
      xyz="0 1 0" />
    <limit
      lower="-2.96706"
      upper="2.96706"
      effort="12.4"
      velocity="6.28" />
  </joint>
  <link
    name="Link_arm_l_06">
    <inertial>
      <origin
        xyz="0 8.95877202866657E-07 0.00166373234012217"
        rpy="0 0 0" />
      <mass
        value="0.280000012776158" />
      <inertia
        ixx="0.000145596926990102"
        ixy="7.70263046256849E-10"
        ixz="-2.14557176368931E-07"
        iyy="0.000156926535065694"
        iyz="-2.41022657678511E-09"
        izz="0.000104981940665913" />
    </inertial>
    <visual>
      <origin
        xyz="0.0265 0 0"
        rpy="0 0 0" />
      <geometry>
        <mesh
          filename="package://AzureLoong/meshes/Link_arm_l_06.STL" />
      </geometry>
      <material
        name="">
        <color
          rgba="0.698039215686274 0.698039215686274 0.698039215686274 1" />
      </material>
    </visual>
    <collision>
      <origin
        xyz="0.0265 0 0"
        rpy="0 0 0" />
      <geometry>
        <mesh
          filename="package://AzureLoong/meshes/Link_arm_l_06.STL" />
      </geometry>
    </collision>
  </link>
  <joint
    name="J_arm_l_06"
    type="revolute">
    <origin
      xyz="0 0.1965 0"
      rpy="0 0 0" />
    <parent
      link="Link_arm_l_05" />
    <child
      link="Link_arm_l_06" />
    <axis
      xyz="-1 0 0" />
    <limit
      lower="-1.8326"
      upper="1.8326"
      effort="12.4"
      velocity="6.28" />
  </joint>
  <link
    name="Link_arm_l_07">
    <inertial>
      <origin
        xyz="-0.0077872 0.15705 -0.027733"
        rpy="0 0 0" />
      <mass
        value="0.61354" />
      <inertia
        ixx="0.0025964"
        ixy="4.66E-05"
        ixz="0.0001089"
        iyy="0.0007306"
        iyz="-1.47E-05"
        izz="0.00301" />
    </inertial>
    <visual>
      <origin
        xyz="0 0 0.0318"
        rpy="0 0 0" />
      <geometry>
        <mesh
          filename="package://AzureLoong/meshes/Link_arm_l_07.STL" />
      </geometry>
      <material
        name="">
        <color
          rgba="0.77647 0.75686 0.73725 1" />
      </material>
    </visual>
    <collision>
      <origin
        xyz="0 0 0.0318"
        rpy="0 0 0" />
      <geometry>
        <mesh
          filename="package://AzureLoong/meshes/Link_arm_l_07.STL" />
      </geometry>
    </collision>
  </link>
  <joint
    name="J_arm_l_07"
    type="revolute">
    <origin
      xyz="0 0 0"
      rpy="0 0 0" />
    <parent
      link="Link_arm_l_06" />
    <child
      link="Link_arm_l_07" />
    <axis
      xyz="0 0 1" />
    <limit
      lower="-1.04720"
      upper="1.04720"
      effort="12.4"
      velocity="6.28" />
  </joint>
  <!-- <link
    name="Link_waist_pitch">
    <inertial>
      <origin
        xyz="-0.00073496 0.049925 -2.9695E-05"
        rpy="0 0 0" />
      <mass
        value="2.6964" />
      <inertia
        ixx="0.0051971"
        ixy="4.37E-05"
        ixz="-3E-07"
        iyy="0.0047413"
        iyz="-6E-06"
        izz="0.0061906" />
    </inertial>
    <visual>
      <origin
        xyz="0 0 0"
        rpy="0 0 0" />
      <geometry>
        <mesh
          filename="package://AzureLoong/meshes/Link_waist_pitch.STL" />
      </geometry>
      <material
        name="">
        <color
          rgba="0.69804 0.69804 0.69804 1" />
      </material>
    </visual>
    <collision>
      <origin
        xyz="0 0 0"
        rpy="0 0 0" />
      <geometry>
        <mesh
          filename="package://AzureLoong/meshes/Link_waist_pitch.STL" />
      </geometry>
    </collision>
  </link>
  <joint
    name="J_waist_pitch"
    type="revolute">
    <origin
      xyz="0 -0.0655 0"
      rpy="0 0 0" />
    <parent
      link="base_link" />
    <child
      link="Link_waist_pitch" />
    <axis
      xyz="0 -1 0" />
    <limit
      lower="-0.29671"
      upper="0.78540"
      effort="315"
      velocity="3.72" />
  </joint>
  <link
    name="Link_waist_roll">
    <inertial>
      <origin
        xyz="-0.0037424 -0.001 -0.016856"
        rpy="0 0 0" />
      <mass
        value="2.9806" />
      <inertia
        ixx="0.0071327"
        ixy="0"
        ixz="0.00358"
        iyy="0.018825"
        iyz="0"
        izz="0.016056" />
    </inertial>
    <visual>
      <origin
        xyz="0 0 0"
        rpy="0 0 0" />
      <geometry>
        <mesh
          filename="package://AzureLoong/meshes/Link_waist_roll.STL" />
      </geometry>
      <material
        name="">
        <color
          rgba="0.8902 0.8902 0.91373 1" />
      </material>
    </visual>
    <collision>
      <origin
        xyz="0 0 0"
        rpy="0 0 0" />
      <geometry>
        <mesh
          filename="package://AzureLoong/meshes/Link_waist_roll.STL" />
      </geometry>
    </collision>
  </link>
  <joint
    name="J_waist_roll"
    type="revolute">
    <origin
      xyz="-0.064 0.0655 0"
      rpy="0 0 0" />
    <parent
      link="Link_waist_pitch" />
    <child
      link="Link_waist_roll" />
    <axis
      xyz="1 0 0" />
    <limit
      lower="-0.69813"
      upper="0.69813"
      effort="315"
      velocity="3.72" />
  </joint>
  <link
    name="Link_waist_yaw">
    <inertial>
      <origin
        xyz="-0.096172 -0.001 -0.057836"
        rpy="0 0 0" />
      <mass
        value="7.3588" />
      <inertia
        ixx="0.091635"
        ixy="0"
        ixz="-0.0058036"
        iyy="0.032766"
        iyz="0"
        izz="0.10764" />
    </inertial>
    <visual>
      <origin
        xyz="0 0 0"
        rpy="0 0 0" />
      <geometry>
        <mesh
          filename="package://AzureLoong/meshes/Link_waist_yaw.STL" />
      </geometry>
      <material
        name="">
        <color
          rgba="0.8902 0.8902 0.91373 1" />
      </material>
    </visual>
    <collision>
      <origin
        xyz="0 0 0"
        rpy="0 0 0" />
      <geometry>
        <mesh
          filename="package://AzureLoong/meshes/Link_waist_yaw.STL" />
      </geometry>
    </collision>
  </link>
  <joint
    name="J_waist_yaw"
    type="revolute">
    <origin
      xyz="0.0675 0 -0.098"
      rpy="0 0 0" />
    <parent
      link="Link_waist_roll" />
    <child
      link="Link_waist_yaw" />
    <axis
      xyz="0 0 1" />
    <limit
      lower="-0.78540"
      upper="0.78540"
      effort="121"
      velocity="5.92" />
  </joint> -->
</robot>